<?xml version="1.0"?>

<robot name="mecanum_base" xmlns:xacro="http://www.ros.org/wiki/xacro">

  <!-- Constants for robot dimensions -->
  <xacro:property name="wheel_rotation_x" value="-1.5708"/> <!-- rotate wheel angle on x axis -->
  <xacro:property name="agv_base_h" value="0.081572" /> <!-- agv_base height : from ground to base center-->
  <xacro:property name="wheel_before_L" value="0.25" /> <!-- wheel before L: x position before base link -->
  <xacro:property name="wheel_after_L" value="-0.25" /> <!-- wheel_after_L: x position after base link -->
  <xacro:property name="wheel_left_W" value="0.3" /> <!-- wheel left W: : y position at left of base link -->
  <xacro:property name="wheel_right_W" value="-0.3" /> <!-- wheel right W: : y position at right of base link -->

  <!-- roller position -->
  <xacro:property name="roller_1_y" value="0"/>  <!-- y: up-down direction at base-link frame-->
  <xacro:property name="roller_2_y" value="0.041781"/>
  <xacro:property name="roller_3_y" value="0.064012"/>
  <xacro:property name="roller_4_y" value="0.056291"/>
  <xacro:property name="roller_5_y" value="0.022231"/>
  <xacro:property name="roller_6_y" value="-0.022231"/>
  <xacro:property name="roller_7_y" value="-0.056291"/>
  <xacro:property name="roller_8_y" value="-0.064012"/>
  <xacro:property name="roller_9_y" value="-0.041781"/>
  <xacro:property name="roller_1_x" value="0.065"/>  <!-- x: left-righ direction at base-link frame-->
  <xacro:property name="roller_2_x" value="0.049792"/>
  <xacro:property name="roller_3_x" value="0.011287"/>
  <xacro:property name="roller_4_x" value="-0.0325"/>
  <xacro:property name="roller_5_x" value="-0.06108"/>
  <xacro:property name="roller_6_x" value="-0.06108"/>
  <xacro:property name="roller_7_x" value="-0.0325"/>
  <xacro:property name="roller_8_x" value="0.011287"/>
  <xacro:property name="roller_9_x" value="0.049792"/>

  <!-- rollor friction -->
  <xacro:property name="roller_friction" value="0.4"/>
  <xacro:property name="roller_dampling" value="0"/>

  <!-- wheel friction -->
  <xacro:property name="roller_friction_wheel" value="0.2"/>
  <xacro:property name="roller_dampling_wheel" value="1.5"/>

  <!-- Import all Gazebo-customization elements, including Gazebo colors -->
  <xacro:include filename="$(find my_mecanum)/urdf/properties.gazebo" />

  <!-- Import Rviz colors -->
  <xacro:include filename="$(find my_mecanum)/urdf/properties.xacro" />

  <!-- Used for fixing robot to Gazebo 'base_link' -->
  <link name="base_footprint"/>

  <!-- Base Link -->
  <joint name="base_joint" type="fixed">
    <parent link="base_footprint"/>
    <child link="base_link"/>
    <origin xyz="0 0 ${agv_base_h}" rpy="0 0 0"/>
  </joint>

  <link name="base_link">
    <collision>
      <origin xyz="0 0 0" rpy="0 0 0"/>
      <geometry>
	<mesh filename="package://my_mecanum/urdf/meshes/amr_base.stl" scale="0.01 0.01 0.01"/>
      </geometry>
    </collision>

    <visual>
      <origin xyz="0 0 0" rpy="0 0 0"/>
      <geometry>
	<mesh filename="package://my_mecanum/urdf/meshes/amr_base.stl" scale="0.01 0.01 0.01"/>
      </geometry>
      <material name="orange"/>
    </visual>

    <inertial>
      <origin xyz="0 0 0" rpy="0 0 0"/>
      <mass value="29.964"/>
      <inertia
	  ixx="0.892684320" ixy="0.0" ixz="0.0"
	  iyy="1.966612482" iyz="0.0"
	  izz="2.677227828"/>
    </inertial>
  </link>

<xacro:macro name="wheel_" params="index x y stl">
  <joint name="wheel_joint${index}" type="continuous">
    <parent link="base_link"/>
    <child link="wheel_${index}"/>
    <origin xyz="${x} ${y} 0" rpy="${wheel_rotation_x} 0 0"/>
    <axis xyz="0 0 1"/>
    <dynamics damping="${roller_dampling_wheel}" friction="${roller_friction_wheel}"/>
  </joint>

  <link name="wheel_${index}">
    <collision>
      <origin xyz="0 0 0" rpy="0 0 0"/>
      <geometry>
	<mesh filename="${stl}" scale="0.01 0.01 0.01"/>
      </geometry>
    </collision>

    <visual>
      <origin xyz="0 0 0" rpy="0 0 0"/>
      <geometry>
	<mesh filename="${stl}" scale="0.01 0.01 0.01"/>
      </geometry>
      <material name="white"/>
    </visual>

    <inertial>
      <origin xyz="0 0 0" rpy="0 0 0"/>
      <mass value="1.7"/>
      <inertia
	  ixx="0.004248052" ixy="0.0" ixz="0.0"
	  iyy="0.004248045" iyz="0.0"
	  izz="0.004879970"/>
    </inertial>
  </link>
</xacro:macro>

<wheel_ index="1" x="${wheel_after_L}" y="${wheel_left_W}" stl="package://my_mecanum/urdf/meshes/wheel_left_back.stl"/>
<wheel_ index="2" x="${wheel_before_L}" y="${wheel_left_W}" stl="package://my_mecanum/urdf/meshes/wheel_left_front.stl"/>
<wheel_ index="3" x="${wheel_before_L}" y="${wheel_right_W}" stl="package://my_mecanum/urdf/meshes/wheel_right_front.stl"/>
<wheel_ index="4" x="${wheel_after_L}" y="${wheel_right_W}" stl="package://my_mecanum/urdf/meshes/wheel_right_back.stl"/>


<xacro:macro name="roller_" params="index parent x y roll yaw">
  <joint name="roller_${index}_joint" type="fixed">
    <parent link="${parent}"/>
    <child link="roller_${index}"/>
    <origin xyz="${x} ${y} 0" rpy="${roll} 0 ${yaw}"/>
    <axis xyz="0 0 1"/>
    <dynamics damping="${roller_dampling}" friction="${roller_friction}"/>
  </joint>

<link name="roller_${index}">
  <collision>
      <origin xyz="0 0 0" rpy="0 0 0"/>
      <geometry>
	<mesh filename="package://my_mecanum/urdf/meshes/roller.stl" scale="0.01 0.01 0.01"/>
      </geometry>
    </collision>

    <visual>
      <origin xyz="0 0 0" rpy="0 0 0"/>
      <geometry>
	<mesh filename="package://my_mecanum/urdf/meshes/roller.stl" scale="0.01 0.01 0.01"/>
      </geometry>
      <material name="black"/>
    </visual>

    <inertial>
      <origin xyz="0 0 0" rpy="0 0 0"/>
      <mass value="0.124"/>
      <inertia
	  ixx="0.000051893" ixy="0.0" ixz="0.0"
	  iyy="0.000051893" iyz="0.0"
	  izz="0.000013891"/>
    </inertial>
  </link>
</xacro:macro>


<roller_ index="1_1" parent="wheel_1" x="${roller_1_y}" y="${roller_1_x}" roll="0.7854" yaw="1.5708" />
<roller_ index="1_2" parent="wheel_1" x="${roller_2_y}" y="${roller_2_x}" roll="0.7854" yaw="0.8727" />
<roller_ index="1_3" parent="wheel_1" x="${roller_3_y}" y="${roller_3_x}" roll="0.7854" yaw="0.1746" />
<roller_ index="1_4" parent="wheel_1" x="${roller_4_y}" y="${roller_4_x}" roll="0.7854" yaw="-0.5235" />
<roller_ index="1_5" parent="wheel_1" x="${roller_5_y}" y="${roller_5_x}" roll="0.7854" yaw="-1.2216" />
<roller_ index="1_6" parent="wheel_1" x="${roller_6_y}" y="${roller_6_x}" roll="0.7854" yaw="4.3632" />
<roller_ index="1_7" parent="wheel_1" x="${roller_7_y}" y="${roller_7_x}" roll="0.7854" yaw="3.6651" />
<roller_ index="1_8" parent="wheel_1" x="${roller_8_y}" y="${roller_8_x}" roll="0.7854" yaw="2.967" />
<roller_ index="1_9" parent="wheel_1" x="${roller_9_y}" y="${roller_9_x}" roll="0.7854" yaw="2.2689" />

<roller_ index="2_1" parent="wheel_2" x="${roller_1_x}" y="${roller_1_y}" roll="-0.7854" yaw="0" />
<roller_ index="2_2" parent="wheel_2" x="${roller_2_x}" y="${roller_2_y}" roll="-0.7854" yaw="0.6981" />
<roller_ index="2_3" parent="wheel_2" x="${roller_3_x}" y="${roller_3_y}" roll="-0.7854" yaw="1.3962" />
<roller_ index="2_4" parent="wheel_2" x="${roller_4_x}" y="${roller_4_y}" roll="-0.7854" yaw="2.0943" />
<roller_ index="2_5" parent="wheel_2" x="${roller_5_x}" y="${roller_5_y}" roll="-0.7854" yaw="2.7924" />
<roller_ index="2_6" parent="wheel_2" x="${roller_6_x}" y="${roller_6_y}" roll="-0.7854" yaw="-2.7924" />
<roller_ index="2_7" parent="wheel_2" x="${roller_7_x}" y="${roller_7_y}" roll="-0.7854" yaw="-2.0943" />
<roller_ index="2_8" parent="wheel_2" x="${roller_8_x}" y="${roller_8_y}" roll="-0.7854" yaw="-1.3962" />
<roller_ index="2_9" parent="wheel_2" x="${roller_9_x}" y="${roller_9_y}" roll="-0.7854" yaw="-0.6981" />

<roller_ index="3_1" parent="wheel_3" x="${roller_1_y}" y="${roller_1_x}" roll="0.7854" yaw="1.5708" />
<roller_ index="3_2" parent="wheel_3" x="${roller_2_y}" y="${roller_2_x}" roll="0.7854" yaw="0.8727" />
<roller_ index="3_3" parent="wheel_3" x="${roller_3_y}" y="${roller_3_x}" roll="0.7854" yaw="0.1746" />
<roller_ index="3_4" parent="wheel_3" x="${roller_4_y}" y="${roller_4_x}" roll="0.7854" yaw="-0.5235" />
<roller_ index="3_5" parent="wheel_3" x="${roller_5_y}" y="${roller_5_x}" roll="0.7854" yaw="-1.2216" />
<roller_ index="3_6" parent="wheel_3" x="${roller_6_y}" y="${roller_6_x}" roll="0.7854" yaw="4.3632" />
<roller_ index="3_7" parent="wheel_3" x="${roller_7_y}" y="${roller_7_x}" roll="0.7854" yaw="3.6651" />
<roller_ index="3_8" parent="wheel_3" x="${roller_8_y}" y="${roller_8_x}" roll="0.7854" yaw="2.967" />
<roller_ index="3_9" parent="wheel_3" x="${roller_9_y}" y="${roller_9_x}" roll="0.7854" yaw="2.2689" />

<roller_ index="4_1" parent="wheel_4" x="${roller_1_x}" y="${roller_1_y}" roll="-0.7854" yaw="0" />
<roller_ index="4_2" parent="wheel_4" x="${roller_2_x}" y="${roller_2_y}" roll="-0.7854" yaw="0.6981" />
<roller_ index="4_3" parent="wheel_4" x="${roller_3_x}" y="${roller_3_y}" roll="-0.7854" yaw="1.3962" />
<roller_ index="4_4" parent="wheel_4" x="${roller_4_x}" y="${roller_4_y}" roll="-0.7854" yaw="2.0943" />
<roller_ index="4_5" parent="wheel_4" x="${roller_5_x}" y="${roller_5_y}" roll="-0.7854" yaw="2.7924" />
<roller_ index="4_6" parent="wheel_4" x="${roller_6_x}" y="${roller_6_y}" roll="-0.7854" yaw="-2.7924" />
<roller_ index="4_7" parent="wheel_4" x="${roller_7_x}" y="${roller_7_y}" roll="-0.7854" yaw="-2.0943" />
<roller_ index="4_8" parent="wheel_4" x="${roller_8_x}" y="${roller_8_y}" roll="-0.7854" yaw="-1.3962" />
<roller_ index="4_9" parent="wheel_4" x="${roller_9_x}" y="${roller_9_y}" roll="-0.7854" yaw="-0.6981" />
</robot>
